File: raw_data/sample_2.dat
[Header]
TITLE,MPMS DC Measurement
BYAPP,MPMS Measurement,2.1,Summary
FILEOPENTIME, 1201241390.953000 1/25/2008, 3:09:50 PM

INFO, APPNAME, MPMS MultiVu Application, Revision 1.56,  Build 67

INFO, NAME, Pr(Ru0.90Rh0.10)4P12
INFO, WEIGHT, 275.200
INFO, AREA, 1.000
INFO, LENGTH, 1.000
INFO, SHAPE, 0
INFO, COMMENT, Sample lot No.2
INFO, SEQUENCE FILE: Rh_doped.seq


INFO, BACKGROUND DATA FILE:, None


STARTUPAXIS,X,4,LINEAR,AUTO,0.000000,0.000000
STARTUPAXIS,Y1,5,LINEAR,AUTO,0.000000,0.000000


STARTUPGROUP,Longitudinal
FIELDGROUP,Longitudinal,1,2,3,4,5,6,7,8,9,15,16,17,18,27,28
FIELDGROUP,Transverse,1,2,3,4,10,11,12,13,14,19,20,21,22,27,28

PLOT_APPEARANCE,ALL,HORZ_GRID_ON,VERT_GRID_ON,MARKERS_AND_LINES

[Data]
Time,Comment,Field (Oe),Temperature (K),Long Moment (emu),Long Scan Std Dev,Long Algorithm,Long Reg Fit,Long Percent Error (%),Trans Moment (emu),Trans Scan Std Dev,Trans Algorithm,Trans Reg Fit,Trans Percent Error (%),Long Moment [w/o ABS] (emu),Long Scan Std Dev [w/o ABS],Long Reg Fit [w/o ABS],Long Percent Error [w/o ABS] (%),Trans Moment [w/o ABS] (emu),Trans Scan Std Dev [w/o ABS],Trans Reg Fit [w/o ABS],Trans Percent Error [w/o ABS] (%),Points per Scan,Scans per Measurement,Scan Length (cm),Delta Temp (K),Rot Position (deg),Error,EC Comp. Running,Using ABS,
1201241390.953,,1.000000e+003,2.003690e+000,2.252852e-002,3.640434e-006,3,9.796095e-001,1.615922e-002,,,,,,,,,,,,,,32,2,4.000000e+000,3.828049e-003,0.000000e+000,0,,0,
1201242757.843,,1.000000e+003,5.996077e+000,1.886540e-002,3.217649e-006,3,9.798272e-001,1.705582e-002,,,,,,,,,,,,,,32,2,4.000000e+000,4.761219e-003,0.000000e+000,0,,0,
1201244081.781,,1.000000e+003,1.000068e+001,1.609423e-002,1.600264e-006,3,9.799269e-001,9.943089e-003,,,,,,,,,,,,,,32,2,4.000000e+000,8.055687e-003,0.000000e+000,0,,0,
1201244240.640,,1.000000e+003,1.399941e+001,1.376461e-002,7.079357e-007,3,9.799948e-001,5.143157e-003,,,,,,,,,,,,,,32,2,4.000000e+000,7.019997e-003,0.000000e+000,0,,0,
1201244403.875,,1.000000e+003,1.796862e+001,1.195064e-002,2.137635e-006,3,9.800808e-001,1.788720e-002,,,,,,,,,,,,,,32,2,4.000000e+000,1.698112e-002,0.000000e+000,0,,0,
1201244573.671,,1.000000e+003,2.193834e+001,1.054455e-002,1.665459e-006,3,9.801402e-001,1.579450e-002,,,,,,,,,,,,,,32,2,4.000000e+000,1.213074e-002,0.000000e+000,0,,0,
1201244753.218,,1.000000e+003,2.591024e+001,9.440860e-003,1.942717e-007,3,9.802433e-001,2.057776e-003,,,,,,,,,,,,,,32,2,4.000000e+000,3.453064e-002,0.000000e+000,0,,0,
1201244937.609,,1.000000e+003,2.989078e+001,8.561464e-003,3.694441e-007,3,9.803299e-001,4.315197e-003,,,,,,,,,,,,,,32,2,4.000000e+000,4.150391e-003,0.000000e+000,0,,0,
1201245132.921,,1.000000e+003,3.386163e+001,7.843515e-003,7.764243e-007,3,9.805082e-001,9.898933e-003,,,,,,,,,,,,,,32,2,4.000000e+000,1.369095e-002,0.000000e+000,0,,0,
1201245343.468,,1.000000e+003,3.783279e+001,7.243126e-003,2.351004e-007,3,9.806287e-001,3.245841e-003,,,,,,,,,,,,,,32,2,4.000000e+000,1.866150e-002,0.000000e+000,0,,0,
1201245564.906,,1.000000e+003,4.180322e+001,6.733429e-003,2.835036e-007,3,9.808252e-001,4.210390e-003,,,,,,,,,,,,,,32,2,4.000000e+000,4.890060e-002,0.000000e+000,0,,0,
1201245804.593,,1.000000e+003,4.577222e+001,6.289370e-003,7.704971e-008,3,9.809976e-001,1.225078e-003,,,,,,,,,,,,,,32,2,4.000000e+000,1.148987e-002,0.000000e+000,0,,0,
1201246019.562,,1.000000e+003,4.974801e+001,5.906081e-003,6.223333e-008,3,9.810619e-001,1.053716e-003,,,,,,,,,,,,,,32,2,4.000000e+000,4.141998e-002,0.000000e+000,0,,0,
1201246221.984,,1.000000e+003,5.374547e+001,5.570266e-003,2.176492e-007,3,9.811156e-001,3.907340e-003,,,,,,,,,,,,,,32,2,4.000000e+000,1.694107e-002,0.000000e+000,0,,0,
1201246428.015,,1.000000e+003,5.773795e+001,5.275608e-003,5.057622e-007,3,9.811680e-001,9.586804e-003,,,,,,,,,,,,,,32,2,4.000000e+000,9.891891e-002,0.000000e+000,0,,0,
1201246633.015,,1.000000e+003,6.170943e+001,5.006386e-003,6.964109e-007,3,9.811388e-001,1.391045e-002,,,,,,,,,,,,,,32,2,4.000000e+000,7.949829e-002,0.000000e+000,0,,0,
1201246842.500,,1.000000e+003,6.566951e+001,4.766332e-003,8.389857e-007,3,9.811759e-001,1.760234e-002,,,,,,,,,,,,,,32,2,4.000000e+000,6.292725e-002,0.000000e+000,0,,0,
1201247050.890,,1.000000e+003,6.967791e+001,4.548752e-003,4.050049e-007,3,9.813139e-001,8.903648e-003,,,,,,,,,,,,,,32,2,4.000000e+000,4.582977e-002,0.000000e+000,0,,0,
1201247258.078,,1.000000e+003,7.365196e+001,4.349824e-003,1.132697e-007,3,9.814599e-001,2.604005e-003,,,,,,,,,,,,,,32,2,4.000000e+000,5.302429e-002,0.000000e+000,0,,0,
1201247468.515,,1.000000e+003,7.763254e+001,4.166161e-003,4.708708e-008,3,9.814901e-001,1.130227e-003,,,,,,,,,,,,,,32,2,4.000000e+000,1.043854e-001,0.000000e+000,0,,0,
1201247682.734,,1.000000e+003,8.159579e+001,3.998757e-003,4.297004e-007,3,9.815390e-001,1.074585e-002,,,,,,,,,,,,,,32,2,4.000000e+000,1.044693e-001,0.000000e+000,0,,0,
1201247893.218,,1.000000e+003,8.558746e+001,3.845016e-003,2.543629e-007,3,9.815814e-001,6.615391e-003,,,,,,,,,,,,,,32,2,4.000000e+000,2.412415e-002,0.000000e+000,0,,0,
1201248104.812,,1.000000e+003,8.955775e+001,3.703712e-003,5.520250e-007,3,9.815387e-001,1.490464e-002,,,,,,,,,,,,,,32,2,4.000000e+000,1.081696e-001,0.000000e+000,0,,0,
1201248316.453,,1.000000e+003,9.348524e+001,3.571041e-003,9.104393e-008,3,9.816200e-001,2.549507e-003,,,,,,,,,,,,,,32,2,4.000000e+000,2.286835e-001,0.000000e+000,0,,0,
1201248530.015,,1.000000e+003,9.752737e+001,3.445620e-003,1.481725e-008,3,9.818261e-001,4.300315e-004,,,,,,,,,,,,,,32,2,4.000000e+000,9.496307e-002,0.000000e+000,0,,0,
1201248743.515,,1.000000e+003,1.015260e+002,3.329913e-003,2.436615e-007,3,9.818629e-001,7.317352e-003,,,,,,,,,,,,,,32,2,4.000000e+000,1.575012e-001,0.000000e+000,0,,0,
1201248957.859,,1.000000e+003,1.054910e+002,3.222042e-003,9.960500e-008,3,9.819772e-001,3.091363e-003,,,,,,,,,,,,,,32,2,4.000000e+000,5.450439e-002,0.000000e+000,0,,0,
1201249170.937,,1.000000e+003,1.094812e+002,3.121004e-003,1.481725e-008,3,9.819081e-001,4.747592e-004,,,,,,,,,,,,,,32,2,4.000000e+000,8.470154e-002,0.000000e+000,0,,0,
1201249381.468,,1.000000e+003,1.134138e+002,3.027540e-003,8.055646e-007,3,9.820116e-001,2.660789e-002,,,,,,,,,,,,,,32,2,4.000000e+000,1.576004e-001,0.000000e+000,0,,0,
1201249590.390,,1.000000e+003,1.174436e+002,2.937000e-003,5.912083e-007,3,9.822730e-001,2.012967e-002,,,,,,,,,,,,,,32,2,4.000000e+000,1.074982e-001,0.000000e+000,0,,0,
1201249800.390,,1.000000e+003,1.214178e+002,2.851214e-003,1.550872e-007,3,9.823347e-001,5.439340e-003,,,,,,,,,,,,,,32,2,4.000000e+000,1.455994e-001,0.000000e+000,0,,0,
1201250007.078,,1.000000e+003,1.253918e+002,2.771523e-003,1.285809e-007,3,9.824127e-001,4.639359e-003,,,,,,,,,,,,,,32,2,4.000000e+000,3.343964e-001,0.000000e+000,0,,0,
1201250232.453,,1.000000e+003,1.292816e+002,2.697762e-003,1.662825e-007,3,9.824200e-001,6.163719e-003,,,,,,,,,,,,,,32,2,4.000000e+000,4.166107e-001,0.000000e+000,0,,0,
1201250446.515,,1.000000e+003,1.332950e+002,2.630618e-003,1.007573e-007,3,9.825519e-001,3.830176e-003,,,,,,,,,,,,,,32,2,4.000000e+000,1.005096e-001,0.000000e+000,0,,0,
1201250654.359,,1.000000e+003,1.373364e+002,2.560730e-003,2.678630e-007,3,9.827672e-001,1.046042e-002,,,,,,,,,,,,,,32,2,4.000000e+000,1.255951e-001,0.000000e+000,0,,0,
1201250859.406,,1.000000e+003,1.413082e+002,2.495008e-003,7.589743e-008,3,9.828366e-001,3.041971e-003,,,,,,,,,,,,,,32,2,4.000000e+000,1.074066e-001,0.000000e+000,0,,0,
1201251065.781,,1.000000e+003,1.452888e+002,2.433473e-003,3.327297e-007,3,9.827911e-001,1.367304e-002,,,,,,,,,,,,,,32,2,4.000000e+000,1.085052e-001,0.000000e+000,0,,0,
1201251270.437,,1.000000e+003,1.492780e+002,2.374785e-003,7.919015e-008,3,9.827914e-001,3.334625e-003,,,,,,,,,,,,,,32,2,4.000000e+000,1.366119e-001,0.000000e+000,0,,0,
1201251476.312,,1.000000e+003,1.532403e+002,2.318108e-003,2.655581e-007,3,9.830000e-001,1.145581e-002,,,,,,,,,,,,,,32,2,4.000000e+000,1.432037e-001,0.000000e+000,0,,0,
1201251678.125,,1.000000e+003,1.572435e+002,2.263707e-003,4.553835e-007,3,9.831233e-001,2.011672e-002,,,,,,,,,,,,,,32,2,4.000000e+000,1.150055e-001,0.000000e+000,0,,0,
1201251879.656,,1.000000e+003,1.612236e+002,2.212531e-003,2.759301e-007,3,9.830534e-001,1.247124e-002,,,,,,,,,,,,,,32,2,4.000000e+000,1.622009e-001,0.000000e+000,0,,0,
1201252083.312,,1.000000e+003,1.651905e+002,2.163826e-003,3.203819e-007,3,9.829713e-001,1.480627e-002,,,,,,,,,,,,,,32,2,4.000000e+000,1.641998e-001,0.000000e+000,0,,0,
1201252285.031,,1.000000e+003,1.691619e+002,2.116561e-003,4.614751e-007,3,9.831440e-001,2.180306e-002,,,,,,,,,,,,,,32,2,4.000000e+000,1.257935e-001,0.000000e+000,0,,0,
1201252488.468,,1.000000e+003,1.731273e+002,2.070810e-003,2.248929e-007,3,9.832721e-001,1.086015e-002,,,,,,,,,,,,,,32,2,4.000000e+000,1.728973e-001,0.000000e+000,0,,0,
1201252694.000,,1.000000e+003,1.771023e+002,2.027448e-003,1.392822e-007,3,9.833026e-001,6.869827e-003,,,,,,,,,,,,,,32,2,4.000000e+000,1.865997e-001,0.000000e+000,0,,0,
1201252897.296,,1.000000e+003,1.810930e+002,1.986335e-003,4.423773e-007,3,9.832816e-001,2.227103e-002,,,,,,,,,,,,,,32,2,4.000000e+000,9.719849e-002,0.000000e+000,0,,0,
1201253102.062,,1.000000e+003,1.850632e+002,1.946511e-003,4.062396e-007,3,9.833871e-001,2.087014e-002,,,,,,,,,,,,,,32,2,4.000000e+000,1.820984e-001,0.000000e+000,0,,0,
1201253306.046,,1.000000e+003,1.890312e+002,1.907400e-003,4.908626e-007,3,9.836445e-001,2.573464e-002,,,,,,,,,,,,,,32,2,4.000000e+000,1.683044e-001,0.000000e+000,0,,0,
1201253511.265,,1.000000e+003,1.929861e+002,1.870169e-003,3.737240e-007,3,9.837461e-001,1.998344e-002,,,,,,,,,,,,,,32,2,4.000000e+000,1.748962e-001,0.000000e+000,0,,0,
1201253714.015,,1.000000e+003,1.969854e+002,1.834678e-003,4.846888e-007,3,9.837716e-001,2.641819e-002,,,,,,,,,,,,,,32,2,4.000000e+000,2.117920e-001,0.000000e+000,0,,0,
1201253920.328,,1.000000e+003,2.009365e+002,1.800539e-003,3.873065e-007,3,9.838924e-001,2.151059e-002,,,,,,,,,,,,,,32,2,4.000000e+000,1.728058e-001,0.000000e+000,0,,0,
1201254125.687,,1.000000e+003,2.049191e+002,1.766928e-003,4.907803e-007,3,9.840764e-001,2.777591e-002,,,,,,,,,,,,,,32,2,4.000000e+000,1.627960e-001,0.000000e+000,0,,0,
1201254329.734,,1.000000e+003,2.089457e+002,1.734251e-003,5.049390e-007,3,9.841464e-001,2.911569e-002,,,,,,,,,,,,,,32,2,4.000000e+000,1.520996e-001,0.000000e+000,0,,0,
1201254533.843,,1.000000e+003,2.128823e+002,1.703463e-003,5.553177e-007,3,9.841005e-001,3.259934e-002,,,,,,,,,,,,,,32,2,4.000000e+000,1.576996e-001,0.000000e+000,0,,0,
1201254738.578,,1.000000e+003,2.168546e+002,1.673797e-003,3.158544e-007,3,9.840810e-001,1.887053e-002,,,,,,,,,,,,,,32,2,4.000000e+000,1.905975e-001,0.000000e+000,0,,0,
1201254947.312,,1.000000e+003,2.207999e+002,1.644704e-003,3.587421e-007,3,9.843009e-001,2.181196e-002,,,,,,,,,,,,,,32,2,4.000000e+000,1.596985e-001,0.000000e+000,0,,0,
1201255153.375,,1.000000e+003,2.248001e+002,1.616262e-003,4.315113e-007,3,9.843641e-001,2.669810e-002,,,,,,,,,,,,,,32,2,4.000000e+000,1.457977e-001,0.000000e+000,0,,0,
1201255360.328,,1.000000e+003,2.287581e+002,1.589394e-003,4.917681e-007,3,9.841990e-001,3.094060e-002,,,,,,,,,,,,,,32,2,4.000000e+000,1.609039e-001,0.000000e+000,0,,0,
1201255566.359,,1.000000e+003,2.327428e+002,1.563315e-003,4.048403e-007,3,9.841462e-001,2.589627e-002,,,,,,,,,,,,,,32,2,4.000000e+000,2.182007e-001,0.000000e+000,0,,0,
1201255772.734,,1.000000e+003,2.367196e+002,1.537588e-003,3.169245e-007,3,9.843342e-001,2.061180e-002,,,,,,,,,,,,,,32,2,4.000000e+000,1.611938e-001,0.000000e+000,0,,0,
1201255977.500,,1.000000e+003,2.406805e+002,1.512513e-003,3.958676e-007,3,9.844716e-001,2.617283e-002,,,,,,,,,,,,,,32,2,4.000000e+000,2.330933e-001,0.000000e+000,0,,0,
1201256181.921,,1.000000e+003,2.446722e+002,1.488839e-003,4.786795e-007,3,9.843440e-001,3.215119e-002,,,,,,,,,,,,,,32,2,4.000000e+000,1.833038e-001,0.000000e+000,0,,0,
1201256386.640,,1.000000e+003,2.486470e+002,1.465929e-003,4.773624e-007,3,9.844224e-001,3.256382e-002,,,,,,,,,,,,,,32,2,4.000000e+000,1.419067e-001,0.000000e+000,0,,0,
1201256593.515,,1.000000e+003,2.525910e+002,1.443059e-003,3.082812e-007,3,9.846483e-001,2.136303e-002,,,,,,,,,,,,,,32,2,4.000000e+000,2.194977e-001,0.000000e+000,0,,0,
1201256799.281,,1.000000e+003,2.565800e+002,1.420868e-003,3.834375e-007,3,9.847746e-001,2.698615e-002,,,,,,,,,,,,,,32,2,4.000000e+000,1.885986e-001,0.000000e+000,0,,0,
1201257007.500,,1.000000e+003,2.605413e+002,1.399714e-003,3.775106e-007,3,9.847584e-001,2.697055e-002,,,,,,,,,,,,,,32,2,4.000000e+000,2.202148e-001,0.000000e+000,0,,0,
1201257213.046,,1.000000e+003,2.645609e+002,1.379044e-003,4.164471e-007,3,9.847536e-001,3.019825e-002,,,,,,,,,,,,,,32,2,4.000000e+000,1.335144e-001,0.000000e+000,0,,0,
1201257436.968,,1.000000e+003,2.684064e+002,1.358362e-003,1.764899e-007,3,9.848394e-001,1.299285e-002,,,,,,,,,,,,,,32,2,4.000000e+000,1.788025e-001,0.000000e+000,0,,0,
1201257647.140,,1.000000e+003,2.724462e+002,1.338881e-003,2.714850e-007,3,9.850408e-001,2.027701e-002,,,,,,,,,,,,,,32,2,4.000000e+000,1.701965e-001,0.000000e+000,0,,0,
1201257854.093,,1.000000e+003,2.764442e+002,1.320083e-003,2.572440e-007,3,9.849821e-001,1.948695e-002,,,,,,,,,,,,,,32,2,4.000000e+000,1.607056e-001,0.000000e+000,0,,0,
1201258060.343,,1.000000e+003,2.804208e+002,1.302024e-003,5.004115e-007,3,9.848872e-001,3.843337e-002,,,,,,,,,,,,,,32,2,4.000000e+000,1.654968e-001,0.000000e+000,0,,0,
1201258268.718,,1.000000e+003,2.844036e+002,1.284014e-003,2.678630e-007,3,9.850025e-001,2.086137e-002,,,,,,,,,,,,,,32,2,4.000000e+000,1.702881e-001,0.000000e+000,0,,0,
1201258478.562,,1.000000e+003,2.883480e+002,1.266442e-003,3.078696e-007,3,9.849673e-001,2.430981e-002,,,,,,,,,,,,,,32,2,4.000000e+000,1.593018e-001,0.000000e+000,0,,0,
1201258685.406,,1.000000e+003,2.923438e+002,1.250149e-003,3.369279e-007,3,9.848585e-001,2.695101e-002,,,,,,,,,,,,,,32,2,4.000000e+000,2.127991e-001,0.000000e+000,0,,0,
1201258893.406,,1.000000e+003,2.963001e+002,1.234657e-003,6.165623e-007,3,9.848189e-001,4.993793e-002,,,,,,,,,,,,,,32,2,4.000000e+000,1.347046e-001,0.000000e+000,0,,0,
1201259096.609,,1.000000e+003,3.002884e+002,1.219814e-003,6.056963e-007,3,9.849347e-001,4.965479e-002,,,,,,,,,,,,,,32,2,4.000000e+000,2.250061e-001,0.000000e+000,0,,0,
1210315767.218,,1.000000e+003,2.004261e+000,2.482169e-002,1.674021e-006,3,9.857924e-001,6.744185e-003,,,,,,,,,,,,,,32,2,4.000000e+000,2.233982e-003,0.000000e+000,0,,0,
1210317139.500,,1.000000e+003,5.998514e+000,2.081779e-002,4.493908e-006,3,9.857785e-001,2.158686e-002,,,,,,,,,,,,,,32,2,4.000000e+000,1.047897e-002,0.000000e+000,0,,0,
1210318463.390,,1.000000e+003,9.993097e+000,1.890409e-002,3.603556e-006,3,9.857693e-001,1.906231e-002,,,,,,,,,,,,,,32,2,4.000000e+000,1.176548e-002,0.000000e+000,0,,0,
1210318620.687,,1.000000e+003,1.400062e+001,1.657839e-002,2.109977e-006,3,9.857869e-001,1.272727e-002,,,,,,,,,,,,,,32,2,4.000000e+000,9.099960e-003,0.000000e+000,0,,0,
1210318781.515,,1.000000e+003,1.796754e+001,1.468524e-002,1.291406e-006,3,9.858129e-001,8.793905e-003,,,,,,,,,,,,,,32,2,4.000000e+000,1.699448e-003,0.000000e+000,0,,0,
1210318966.609,,1.000000e+003,2.194725e+001,1.323048e-002,8.100365e-008,3,9.859803e-001,6.122502e-004,,,,,,,,,,,,,,32,2,4.000000e+000,9.710312e-003,0.000000e+000,0,,0,
1210319142.375,,1.000000e+003,2.591293e+001,1.209899e-002,1.940072e-006,3,9.858871e-001,1.603499e-002,,,,,,,,,,,,,,32,2,4.000000e+000,2.160072e-002,0.000000e+000,0,,0,
1210319328.656,,1.000000e+003,2.988753e+001,1.118708e-002,1.459335e-006,3,9.858783e-001,1.304482e-002,,,,,,,,,,,,,,32,2,4.000000e+000,2.485085e-002,0.000000e+000,0,,0,
1210319526.062,,1.000000e+003,3.386279e+001,1.042682e-002,1.780704e-006,3,9.859022e-001,1.707811e-002,,,,,,,,,,,,,,32,2,4.000000e+000,2.394867e-002,0.000000e+000,0,,0,
1210319736.046,,1.000000e+003,3.783183e+001,9.778410e-003,1.617385e-006,3,9.859589e-001,1.654037e-002,,,,,,,,,,,,,,32,2,4.000000e+000,3.108978e-002,0.000000e+000,0,,0,
1210319958.546,,1.000000e+003,4.181658e+001,9.211987e-003,1.117550e-006,3,9.859637e-001,1.213148e-002,,,,,,,,,,,,,,32,2,4.000000e+000,9.777069e-003,0.000000e+000,0,,0,
1210320176.218,,1.000000e+003,4.577965e+001,8.704264e-003,1.395456e-006,3,9.859750e-001,1.603187e-002,,,,,,,,,,,,,,32,2,4.000000e+000,4.713058e-002,0.000000e+000,0,,0,
1210320390.609,,1.000000e+003,4.976522e+001,8.254131e-003,1.305894e-006,3,9.859705e-001,1.582109e-002,,,,,,,,,,,,,,32,2,4.000000e+000,4.679871e-002,0.000000e+000,0,,0,
1210320592.437,,1.000000e+003,5.375834e+001,7.849339e-003,7.349357e-007,3,9.859023e-001,9.363025e-003,,,,,,,,,,,,,,32,2,4.000000e+000,5.233002e-002,0.000000e+000,0,,0,
1210320797.125,,1.000000e+003,5.773388e+001,7.484041e-003,5.907144e-007,3,9.858283e-001,7.892988e-003,,,,,,,,,,,,,,32,2,4.000000e+000,2.080917e-002,0.000000e+000,0,,0,
1210321004.843,,1.000000e+003,6.171236e+001,7.145758e-003,2.887720e-007,3,9.858266e-001,4.041167e-003,,,,,,,,,,,,,,32,2,4.000000e+000,7.369995e-002,0.000000e+000,0,,0,
1210321225.937,,1.000000e+003,6.567853e+001,6.838367e-003,1.043793e-006,3,9.859403e-001,1.526378e-002,,,,,,,,,,,,,,32,2,4.000000e+000,8.029175e-002,0.000000e+000,0,,0,
1210321436.609,,1.000000e+003,6.968777e+001,6.557137e-003,6.931182e-007,3,9.859853e-001,1.057044e-002,,,,,,,,,,,,,,32,2,4.000000e+000,1.689148e-002,0.000000e+000,0,,0,
1210321642.750,,1.000000e+003,7.365807e+001,6.297797e-003,2.113928e-007,3,9.859939e-001,3.356615e-003,,,,,,,,,,,,,,32,2,4.000000e+000,4.505157e-002,0.000000e+000,0,,0,
1210321854.328,,1.000000e+003,7.766455e+001,6.058833e-003,8.442540e-007,3,9.859673e-001,1.393427e-002,,,,,,,,,,,,,,32,2,4.000000e+000,8.414459e-002,0.000000e+000,0,,0,
1210322062.687,,1.000000e+003,8.162679e+001,5.839922e-003,5.166283e-007,3,9.859593e-001,8.846493e-003,,,,,,,,,,,,,,32,2,4.000000e+000,5.068970e-002,0.000000e+000,0,,0,
1210322274.921,,1.000000e+003,8.559203e+001,5.636198e-003,1.052354e-006,3,9.859685e-001,1.867135e-002,,,,,,,,,,,,,,32,2,4.000000e+000,7.237244e-002,0.000000e+000,0,,0,
1210322487.234,,1.000000e+003,8.957777e+001,5.447536e-003,7.234112e-007,3,9.860713e-001,1.327960e-002,,,,,,,,,,,,,,32,2,4.000000e+000,5.968475e-002,0.000000e+000,0,,0,
1210322701.328,,1.000000e+003,9.361953e+001,5.270652e-003,9.170233e-007,3,9.862002e-001,1.739867e-002,,,,,,,,,,,,,,32,2,4.000000e+000,8.045197e-002,0.000000e+000,0,,0,
1210322912.140,,1.000000e+003,9.752847e+001,5.105333e-003,9.911095e-007,3,9.863513e-001,1.941322e-002,,,,,,,,,,,,,,32,2,4.000000e+000,2.159119e-002,0.000000e+000,0,,0,
1210323123.890,,1.000000e+003,1.015114e+002,4.951611e-003,8.705958e-007,3,9.863257e-001,1.758207e-002,,,,,,,,,,,,,,32,2,4.000000e+000,1.390076e-002,0.000000e+000,0,,0,
1210323336.359,,1.000000e+003,1.054301e+002,4.807635e-003,7.006914e-007,3,9.863064e-001,1.457455e-002,,,,,,,,,,,,,,32,2,4.000000e+000,1.385956e-001,0.000000e+000,0,,0,
1210323548.015,,1.000000e+003,1.094973e+002,4.673286e-003,1.034903e-006,3,9.863133e-001,2.214508e-002,,,,,,,,,,,,,,32,2,4.000000e+000,1.482010e-001,0.000000e+000,0,,0,
1210323760.515,,1.000000e+003,1.134612e+002,4.544929e-003,8.442540e-007,3,9.864484e-001,1.857574e-002,,,,,,,,,,,,,,32,2,4.000000e+000,1.859055e-001,0.000000e+000,0,,0,
1210323973.078,,1.000000e+003,1.174947e+002,4.425820e-003,1.306552e-006,3,9.864743e-001,2.952114e-002,,,,,,,,,,,,,,32,2,4.000000e+000,3.229980e-001,0.000000e+000,0,,0,
1210324188.953,,1.000000e+003,1.214394e+002,4.312209e-003,3.635166e-007,3,9.863881e-001,8.429939e-003,,,,,,,,,,,,,,32,2,4.000000e+000,1.520004e-001,0.000000e+000,0,,0,
1210324399.218,,1.000000e+003,1.253938e+002,4.207538e-003,9.947315e-007,3,9.863695e-001,2.364165e-002,,,,,,,,,,,,,,32,2,4.000000e+000,2.876053e-001,0.000000e+000,0,,0,
1210324609.718,,1.000000e+003,1.294028e+002,4.106654e-003,1.281198e-006,3,9.863609e-001,3.119811e-002,,,,,,,,,,,,,,32,2,4.000000e+000,3.530884e-002,0.000000e+000,0,,0,
1210324817.500,,1.000000e+003,1.333448e+002,4.012210e-003,7.632531e-007,3,9.864673e-001,1.902326e-002,,,,,,,,,,,,,,32,2,4.000000e+000,1.304016e-001,0.000000e+000,0,,0,
1210325026.250,,1.000000e+003,1.373331e+002,3.920066e-003,9.397430e-007,3,9.865412e-001,2.397263e-002,,,,,,,,,,,,,,32,2,4.000000e+000,1.295013e-001,0.000000e+000,0,,0,
1210325232.687,,1.000000e+003,1.413174e+002,3.833908e-003,9.089561e-007,3,9.864844e-001,2.370835e-002,,,,,,,,,,,,,,32,2,4.000000e+000,1.074066e-001,0.000000e+000,0,,0,
1210325439.734,,1.000000e+003,1.452901e+002,3.751912e-003,6.883437e-007,3,9.863654e-001,1.834648e-002,,,,,,,,,,,,,,32,2,4.000000e+000,1.343994e-001,0.000000e+000,0,,0,
1210325644.984,,1.000000e+003,1.492785e+002,3.674117e-003,6.071780e-007,3,9.864972e-001,1.652582e-002,,,,,,,,,,,,,,32,2,4.000000e+000,7.739258e-002,0.000000e+000,0,,0,
1210325846.593,,1.000000e+003,1.532520e+002,3.598385e-003,9.863351e-007,3,9.866042e-001,2.741049e-002,,,,,,,,,,,,,,32,2,4.000000e+000,1.241913e-001,0.000000e+000,0,,0,
1210326046.000,,1.000000e+003,1.572561e+002,3.527065e-003,1.154593e-006,3,9.865801e-001,3.273524e-002,,,,,,,,,,,,,,32,2,4.000000e+000,1.300964e-001,0.000000e+000,0,,0,
1210326247.515,,1.000000e+003,1.612138e+002,3.459631e-003,9.804081e-007,3,9.865122e-001,2.833852e-002,,,,,,,,,,,,,,32,2,4.000000e+000,1.464996e-001,0.000000e+000,0,,0,
1210326449.984,,1.000000e+003,1.651781e+002,3.393637e-003,1.013500e-006,3,9.866300e-001,2.986471e-002,,,,,,,,,,,,,,32,2,4.000000e+000,1.695099e-001,0.000000e+000,0,,0,
1210326652.531,,1.000000e+003,1.691752e+002,3.330216e-003,9.189989e-007,3,9.867799e-001,2.759578e-002,,,,,,,,,,,,,,32,2,4.000000e+000,1.428986e-001,0.000000e+000,0,,0,
1210326855.281,,1.000000e+003,1.731360e+002,3.269505e-003,1.003622e-006,3,9.868361e-001,3.069645e-002,,,,,,,,,,,,,,32,2,4.000000e+000,1.610107e-001,0.000000e+000,0,,0,
1210327057.640,,1.000000e+003,1.771027e+002,3.212654e-003,9.188342e-007,3,9.867616e-001,2.860048e-002,,,,,,,,,,,,,,32,2,4.000000e+000,1.492004e-001,0.000000e+000,0,,0,
1210327259.359,,1.000000e+003,1.811073e+002,3.157834e-003,9.017121e-007,3,9.867473e-001,2.855477e-002,,,,,,,,,,,,,,32,2,4.000000e+000,1.748962e-001,0.000000e+000,0,,0,
1210327464.984,,1.000000e+003,1.850536e+002,3.103938e-003,8.147842e-007,3,9.869616e-001,2.625001e-002,,,,,,,,,,,,,,32,2,4.000000e+000,1.416016e-001,0.000000e+000,0,,0,
1210327666.156,,1.000000e+003,1.890502e+002,3.052539e-003,1.093842e-006,3,9.870160e-001,3.583385e-002,,,,,,,,,,,,,,32,2,4.000000e+000,1.683044e-001,0.000000e+000,0,,0,
1210327870.109,,1.000000e+003,1.930014e+002,3.004333e-003,7.011853e-007,3,9.869056e-001,2.333914e-002,,,,,,,,,,,,,,32,2,4.000000e+000,1.604004e-001,0.000000e+000,0,,0,
1210328074.781,,1.000000e+003,1.969852e+002,2.958677e-003,8.877180e-007,3,9.868612e-001,3.000389e-002,,,,,,,,,,,,,,32,2,4.000000e+000,1.665039e-001,0.000000e+000,0,,0,
1210328276.531,,1.000000e+003,2.009729e+002,2.912871e-003,9.585116e-007,3,9.869189e-001,3.290608e-002,,,,,,,,,,,,,,32,2,4.000000e+000,1.806946e-001,0.000000e+000,0,,0,
1210328481.640,,1.000000e+003,2.049438e+002,2.869019e-003,4.315113e-007,3,9.869598e-001,1.504038e-002,,,,,,,,,,,,,,32,2,4.000000e+000,1.791992e-001,0.000000e+000,0,,0,
1210328687.046,,1.000000e+003,2.089029e+002,2.827246e-003,7.326308e-007,3,9.868727e-001,2.591323e-002,,,,,,,,,,,,,,32,2,4.000000e+000,1.605072e-001,0.000000e+000,0,,0,
1210328909.750,,1.000000e+003,2.128043e+002,2.788310e-003,3.391504e-007,3,9.866934e-001,1.216330e-002,,,,,,,,,,,,,,32,2,4.000000e+000,9.629822e-002,0.000000e+000,0,,0,
1210329117.000,,1.000000e+003,2.168387e+002,2.749387e-003,5.518603e-007,3,9.868571e-001,2.007212e-002,,,,,,,,,,,,,,32,2,4.000000e+000,1.815033e-001,0.000000e+000,0,,0,
1210329323.937,,1.000000e+003,2.208484e+002,2.710498e-003,8.528152e-007,3,9.869072e-001,3.146341e-002,,,,,,,,,,,,,,32,2,4.000000e+000,1.690979e-001,0.000000e+000,0,,0,
1210329529.703,,1.000000e+003,2.248034e+002,2.673791e-003,7.788935e-007,3,9.868065e-001,2.913068e-002,,,,,,,,,,,,,,32,2,4.000000e+000,1.069946e-001,0.000000e+000,0,,0,
1210329734.187,,1.000000e+003,2.287908e+002,2.639161e-003,5.884095e-007,3,9.868038e-001,2.229532e-002,,,,,,,,,,,,,,32,2,4.000000e+000,1.710052e-001,0.000000e+000,0,,0,
1210329940.625,,1.000000e+003,2.327654e+002,2.604378e-003,6.598616e-007,3,9.869503e-001,2.533663e-002,,,,,,,,,,,,,,32,2,4.000000e+000,1.351013e-001,0.000000e+000,0,,0,
1210330145.734,,1.000000e+003,2.367180e+002,2.569910e-003,7.858083e-007,3,9.871142e-001,3.057727e-002,,,,,,,,,,,,,,32,2,4.000000e+000,1.504974e-001,0.000000e+000,0,,0,
1210330351.578,,1.000000e+003,2.407002e+002,2.537140e-003,7.517286e-007,3,9.870472e-001,2.962897e-002,,,,,,,,,,,,,,32,2,4.000000e+000,1.776123e-001,0.000000e+000,0,,0,
1210330556.546,,1.000000e+003,2.446774e+002,2.506021e-003,7.561737e-007,3,9.870151e-001,3.017428e-002,,,,,,,,,,,,,,32,2,4.000000e+000,1.833038e-001,0.000000e+000,0,,0,
1210330761.390,,1.000000e+003,2.486221e+002,2.474866e-003,7.232465e-007,3,9.871444e-001,2.922366e-002,,,,,,,,,,,,,,32,2,4.000000e+000,1.773071e-001,0.000000e+000,0,,0,
1210330966.328,,1.000000e+003,2.526102e+002,2.444166e-003,7.573262e-007,3,9.871957e-001,3.098505e-002,,,,,,,,,,,,,,32,2,4.000000e+000,1.707001e-001,0.000000e+000,0,,0,
1210331170.234,,1.000000e+003,2.566053e+002,2.415013e-003,7.263746e-007,3,9.871075e-001,3.007746e-002,,,,,,,,,,,,,,32,2,4.000000e+000,1.509094e-001,0.000000e+000,0,,0,
1210331374.000,,1.000000e+003,2.605858e+002,2.386108e-003,6.934474e-007,3,9.866854e-001,2.906186e-002,,,,,,,,,,,,,,32,2,4.000000e+000,1.036987e-001,0.000000e+000,0,,0,
1210331579.625,,1.000000e+003,2.645461e+002,2.358034e-003,7.619360e-007,3,9.868011e-001,3.231234e-002,,,,,,,,,,,,,,32,2,4.000000e+000,1.735840e-001,0.000000e+000,0,,0,
1210331786.765,,1.000000e+003,2.685038e+002,2.330346e-003,5.541652e-007,3,9.868340e-001,2.378038e-002,,,,,,,,,,,,,,32,2,4.000000e+000,1.513062e-001,0.000000e+000,0,,0,
1210331994.578,,1.000000e+003,2.724784e+002,2.304435e-003,5.225551e-007,3,9.867343e-001,2.267606e-002,,,,,,,,,,,,,,32,2,4.000000e+000,1.559753e-001,0.000000e+000,0,,0,
1210332201.781,,1.000000e+003,2.764692e+002,2.280063e-003,5.619031e-007,3,9.866377e-001,2.464420e-002,,,,,,,,,,,,,,32,2,4.000000e+000,1.607056e-001,0.000000e+000,0,,0,
1210332411.125,,1.000000e+003,2.803970e+002,2.255572e-003,3.860717e-007,3,9.866977e-001,1.711635e-002,,,,,,,,,,,,,,32,2,4.000000e+000,1.804810e-001,0.000000e+000,0,,0,
1210332619.921,,1.000000e+003,2.843744e+002,2.230394e-003,3.579189e-007,3,9.865860e-001,1.604734e-002,,,,,,,,,,,,,,32,2,4.000000e+000,2.785034e-001,0.000000e+000,0,,0,
1210332825.281,,1.000000e+003,2.883728e+002,2.205283e-003,8.475468e-007,3,9.862409e-001,3.843257e-002,,,,,,,,,,,,,,32,2,4.000000e+000,1.911011e-001,0.000000e+000,0,,0,
1210333034.250,,1.000000e+003,2.923399e+002,2.184957e-003,2.239051e-007,3,9.863295e-001,1.024758e-002,,,,,,,,,,,,,,32,2,4.000000e+000,2.127991e-001,0.000000e+000,0,,0,
1210333240.500,,1.000000e+003,2.962763e+002,2.166758e-003,8.129732e-007,3,9.867214e-001,3.752027e-002,,,,,,,,,,,,,,32,2,4.000000e+000,2.354736e-001,0.000000e+000,0,,0,
1210333443.171,,1.000000e+003,3.002955e+002,2.147735e-003,8.654922e-007,3,9.869955e-001,4.029791e-002,,,,,,,,,,,,,,32,2,4.000000e+000,2.335815e-001,0.000000e+000,0,,0,